Workbook

Sheet Summary
A1: BugBot stack BOM
A2: Source: KiCad schematic netlists (golden, after the 2026-09-07 rework); LCSC fields; stock, price and part class read from jlcpcb.com part pages on 2026-09-06 (rework parts on 2026-09-07).
A3: Yellow cells are inputs you can change. Everything else is a formula.
A5: Boards to build (sets) | B5: 5
A6: USD per GBP | B6: 1.27
A7: JLC extended-part fee per line, USD | B7: 3
A8: Thin-stock threshold (pieces) | B8: 5000
A10: Board | B10: Lines | C10: Parts per board | D10: JLC parts cost per board (USD) | E10: Extended lines | F10: Extended fee per order (USD) | G10: Parts cost per set of boards (USD) | H10: Parts cost per set (GBP) | I10: Lines with no JLC code | J10: Lines below thin-stock | K10: Lines short for the run
A11: BugBot Motion Board | B11: 30 | C11: =Motion!B34 -> 63 | D11: =Motion!J34 -> 16.6321 | E11: =Motion!B35 -> 18 | F11: =E11*$B$7 -> 54 | G11: =D11*$B$5 -> 83.1605 | H11: =G11/$B$6 -> 65.480709 | I11: =Motion!B36 -> 2 | J11: =Motion!B37 -> 3 | K11: =Motion!B38 -> 0
A12: BugBot Vision Board | B12: 15 | C12: =Vision!B19 -> 27 | D12: =Vision!J19 -> 1.199 | E12: =Vision!B20 -> 5 | F12: =E12*$B$7 -> 15 | G12: =D12*$B$5 -> 5.995 | H12: =G12/$B$6 -> 4.7204724 | I12: =Vision!B21 -> 3 | J12: =Vision!B22 -> 1 | K12: =Vision!B23 -> 0
A13: BugBot Odometry Board | B13: 13 | C13: =Odometry!B17 -> 23 | D13: =Odometry!J17 -> 9.9899 | E13: =Odometry!B18 -> 3 | F13: =E13*$B$7 -> 9 | G13: =D13*$B$5 -> 49.9495 | H13: =G13/$B$6 -> 39.330315 | I13: =Odometry!B19 -> 1 | J13: =Odometry!B20 -> 1 | K13: =Odometry!B21 -> 0
A14: Stack (one of each) | B14: =SUM(B11:B13) -> 58 | C14: =SUM(C11:C13) -> 113 | D14: =SUM(D11:D13) -> 27.821 | E14: =SUM(E11:E13) -> 26 | F14: =SUM(F11:F13) -> 78 | G14: =SUM(G11:G13) -> 139.105 | H14: =SUM(H11:H13) -> 109.5315 | I14: =SUM(I11:I13) -> 6 | ... K14: =SUM(K11:K13) -> 0
A16: Parts cost per robot, GBP (JLC parts only, no PCB, assembly, or the three hand-soldered parts) | B16: =D14/$B$6 -> 21.906299
A17: Extended-part fees for one order of all three boards, USD | B17: =F14 -> 78
A19: Not on JLC (bought and hand-soldered): Motion J8/J9 and Vision J8/J9 2x5 2.00 mm stack connectors, Vision U3 ESP32-P4 module, Odometry U2 PMW3360 sensor + LM19 lens. Mounting holes H1-H4 have no part.
A20: Thin stock on the day: DRV8830 (C127591) 129 pcs = 32 Motion boards; camera 22P top-contact connector (C2911765) 473; GH1.25 10-pin (C3029376) 1,796; ETA6003 (C5455585) 2,234. Nothing was pre-order or idle.
A21: Rework 2026-09-07: switch SW3 now on Vision (underside, top edge); servo connectors J10/J11 (side-entry GH1.25 3P) back on Motion; ToF J7 side-entry on the Vision underside; camera J3 = 22P 0.5 mm top-contact horizontal for the OV5647 spy module (pinout mirrored: pin k = Pi Zero pin 23-k). See the Flags sheet for the open items and the decisions taken.

Sheet Costing
A1: Order costing for the run (JLCPCB fees from jlcpcb.com/help/article/pcb-assembly-price and the quote form, read 2026-09-09)
A2: Yellow cells are inputs. Board part counts and Extended-line counts come from the board sheets; parts cost from the Summary sheet.
A4: Sets to build | B4: =Summary!B5 -> 5 | C4: sets, from the Summary sheet
A5: USD per GBP | B5: =Summary!B6 -> 1.27 | C5: from the Summary sheet
A6: PCB price, 4-layer 40x40 mm, 5 pcs (USD) | B6: 7 | C6: quote form 2026-09-09, JLC04161H-3313 stackup, ENIG adds ~$15 per order
A7: Economic assembly setup (USD) | B7: 8.18 | C7: top side only
A8: Economic stencil (USD) | B8: 1.53
A9: Economic feeder fee per Extended part type (USD) | B9: 3.07 | C9: Basic parts free
A10: Standard both-sides setup (USD) | B10: 51.12 | C10: needed when parts sit on both sides
A11: Standard both-sides stencil (USD) | B11: 16.42
A12: Standard feeder fee per part type (USD) | B12: 1.53 | C12: Basic and Extended
A13: Solder joint (USD) | B13: 0.0016 | C13: per joint; about 2.5 joints per part on these boards
A14: Shipping, DHL Express DDP incl. duties and VAT (USD) | B14: 28 | C14: one parcel, quote form estimate for ~0.25 kg
A15: ACTUAL JLC invoice, all orders incl. parts and shipping (USD) | B15: =SUM(K18:K21)+B16 -> 420.93 | C15: invoice 2444722A2026090908545474 of 09/09/2026: per-order totals in column K, shipping K21, discount B16; the totals below use it instead of the estimate
A16: JLC discount on the invoice (USD, negative) | B16: -19.38 | C16: invoice line 'Discount'
A17: Board | B17: Assembly type | C17: JLC lines | D17: Extended lines | E17: Parts per board | F17: Setup + stencil (USD) | G17: Feeder fees (USD) | H17: Joints (USD) | I17: PCB (USD) | J17: Board order estimate (USD) | K17: ACTUAL order total incl. parts (USD) | L17: JLC order number
A18: BugBot Motion Board | B18: Standard both sides | C18: =COUNTA(Motion!E3:E32) -> 28 | D18: =Motion!B35 -> 18 | E18: =Motion!B34-Motion!B36 -> 61 | F18: =IF(B18="Economic top only",$B$7+$B$8,$B$10+$B$11) -> 67.54 | G18: =IF(B18="Economic top only",D18*$B$9,C18*$B$12) -> 42.84 | H18: =E18*2.5*$B$4*$B$13 -> 1.22 | I18: =$B$6*$B$4/5 -> 7 | J18: =SUM(F18:I18) -> 118.6 | K18: 200.34 | L18: SMT026090960104-Y13
A19: BugBot Vision Board | B19: Economic top only | C19: =COUNTA(Vision!E3:E17) -> 12 | D19: =Vision!B20 -> 5 | E19: =Vision!B19-Vision!B21 -> 24 | F19: =IF(B19="Economic top only",$B$7+$B$8,$B$10+$B$11) -> 9.71 | G19: =IF(B19="Economic top only",D19*$B$9,C19*$B$12) -> 15.35 | H19: =E19*2.5*$B$4*$B$13 -> 0.48 | I19: =$B$6*$B$4/5 -> 7 | J19: =SUM(F19:I19) -> 32.54 | K19: 103.67 | L19: SMT026090960086-Y12
A20: BugBot Odometry Board | B20: Economic top only | C20: =COUNTA(Odometry!E3:E15) -> 12 | D20: =Odometry!B18 -> 3 | E20: =Odometry!B17-Odometry!B19 -> 22 | F20: =IF(B20="Economic top only",$B$7+$B$8,$B$10+$B$11) -> 9.71 | G20: =IF(B20="Economic top only",D20*$B$9,C20*$B$12) -> 9.21 | H20: =E20*2.5*$B$4*$B$13 -> 0.44 | I20: =$B$6*$B$4/5 -> 7 | J20: =SUM(F20:I20) -> 26.36 | K20: 112.4 | L20: SMT026090960075-Y11
J21: Actual shipping, DHL Express (USD) | K21: 23.9
A22: JLC assembly and PCBs, three orders (USD) | B22: =SUM(J18:J20) -> 177.5
A23: JLC components for the run (USD, Summary sheet) | B23: =Summary!G14 -> 139.105
A24: Shipping (USD) | B24: =B14 -> 28
A25: JLC total, estimate (USD) | B25: =SUM(B22:B24) -> 344.605
A26: JLC total used below: actual invoice if entered, else the estimate (USD) | B26: =IF(B15>0,B15,B25) -> 420.93
A27: JLC total used below (GBP) | B27: =B26/B5 -> 331.44094 | F27: Vision underside parts hand-soldered by you for the Economic option: C20, C21, J7 (ToF), SW3 (switch).
A28: Actual minus estimate (USD) | B28: =IF(B15>0,B15-B25,0) -> 76.325
A29: Bought elsewhere (per robot) | B29: Qty per robot | C29: Unit price (USD) | D29: Per robot (USD) | E29: For the run (USD) | F29: Note
A30: ESP32-P4 module (Waveshare) | B30: 1 | C30: 20 | D30: =B30*C30 -> 20 | E30: =D30*$B$4 -> 100 | F30: Vision U3, hand-soldered
A31: OV5647 spy camera, 120 deg, 22-pin flex | B31: 1 | C31: 8 | D31: =B31*C31 -> 8 | E31: =D31*$B$4 -> 40 | F31: or Pi Zero camera board + short cable
A32: VL53L5CX ToF module + 6-way GH cable | B32: 1 | C32: 8 | D32: =B32*C32 -> 8 | E32: =D32*$B$4 -> 40 | F32: cable to the board's pin order
A33: PMW3360 sensor + LM19 lens | B33: 1 | C33: 15 | D33: =B33*C33 -> 15 | E33: =D33*$B$4 -> 75 | F33: Odometry U2
A34: 2x5 2.00 mm socket 5.6 mm + header | B34: 2 | C34: 1 | D34: =B34*C34 -> 2 | E34: =D34*$B$4 -> 10 | F34: stack, hand-soldered
A35: GH1.25 10-way REVERSE cable | B35: 1 | C35: 1.5 | D35: =B35*C35 -> 1.5 | E35: =D35*$B$4 -> 7.5 | F35: cavity 1 to cavity 10
A36: 1S LiPo 450 mAh 25C (Syma type) | B36: 1 | C36: 4 | D36: =B36*C36 -> 4 | E36: =D36*$B$4 -> 20 | F36: or 2 in parallel
A37: 0615 coreless motor | B37: 4 | C37: 2 | D37: =B37*C37 -> 8 | E37: =D37*$B$4 -> 40
A38: HK-5320 servo | B38: 2 | C38: 6 | D38: =B38*C38 -> 12 | E38: =D38*$B$4 -> 60
A39: WS2812 LED ball | B39: 1 | C39: 1 | D39: =B39*C39 -> 1 | E39: =D39*$B$4 -> 5
A41: Bought elsewhere, per robot (USD) | B41: =SUM(D30:D39) -> 79.5
A42: Bought elsewhere, for the run (USD) | B42: =SUM(E30:E39) -> 397.5
...

Sheet Parts
A1: Unique JLC parts across the three boards. Stock, price (1-piece, USD) and class read live from jlcpcb.com on 2026-09-06 (2026-09-07 for the rework parts). None were idle / pre-order.
A2: LCSC | B2: MPN | C2: Manufacturer | D2: JLC description | E2: Class | F2: Stock | G2: Unit price (USD) | H2: Pre-order / idle | I2: Checked | J2: Total used per set | K2: Needed for run | L2: Stock status | M2: Datasheet
A3: C127591 | B3: DRV8830DGQR | C3: Texas Instruments | D3: -40℃~+85℃ 1 1A 1A 2.75V~6.8V 300nA 450mΩ I2C Yes MSOP-10-EP Brushed DC Motor Drivers ROHS | E3: Extended | F3: 129 | G3: 2.7355 | H3: No | I3: 2026-09-06 | J3: =SUMIF(Motion!$E$3:$E$32,$A3,Motion!$B$3:$B$32)+SUMIF(Vision!$E$3:$E$17,$A3,Vision!$B$3:$B$17)+SUMIF(Odometry!$E$3:$E$15,$A3,Odometry!$B$3:$B$15) -> 4 | K3: =J3*Summary!$B$5 -> 20 | L3: =IF(F3<K3,"SHORT",IF(F3<Summary!$B$8,"Thin","OK")) -> Thin | M3: https://www.ti.com/lit/ds/symlink/drv8830.pdf
A4: C1525 | B4: CL05B104KO5NNNC | C4: Samsung | D4: 100nF 16V X7R ±10% 0402 Multilayer Ceramic Capacitors MLCC - SMD/SMT ROHS | E4: Basic | F4: 37375769 | G4: 0.0051 | H4: No | I4: 2026-09-06 | J4: =SUMIF(Motion!$E$3:$E$32,$A4,Motion!$B$3:$B$32)+SUMIF(Vision!$E$3:$E$17,$A4,Vision!$B$3:$B$17)+SUMIF(Odometry!$E$3:$E$15,$A4,Odometry!$B$3:$B$15) -> 14 | K4: =J4*Summary!$B$5 -> 70 | L4: =IF(F4<K4,"SHORT",IF(F4<Summary!$B$8,"Thin","OK")) -> OK | M4: https://jlcpcb.com/partdetail/C1525
A5: C15483 | B5: TPS63020DSJR | C5: Texas Instruments | D5: -40℃~+85℃@(TA) 1 1.2V~5.5V 1.8V~5.5V 2.4MHz 3A 50uA Adjustable Buck-Boost Buck-Boost Built-in Yes VSON-14-EP(3 | E5: Extended | F5: 13311 | G5: 0.9584 | H5: No | I5: 2026-09-06 | J5: =SUMIF(Motion!$E$3:$E$32,$A5,Motion!$B$3:$B$32)+SUMIF(Vision!$E$3:$E$17,$A5,Vision!$B$3:$B$17)+SUMIF(Odometry!$E$3:$E$15,$A5,Odometry!$B$3:$B$15) -> 1 | K5: =J5*Summary!$B$5 -> 5 | L5: =IF(F5<K5,"SHORT",IF(F5<Summary!$B$8,"Thin","OK")) -> OK | M5: https://www.ti.com/lit/ds/symlink/tps63020.pdf
A6: C15850 | B6: CL21A106KAYNNNE | C6: Samsung | D6: 10uF 25V X5R ±10% 0805 Multilayer Ceramic Capacitors MLCC - SMD/SMT ROHS | E6: Basic | F6: 7849987 | G6: 0.0847 | H6: No | I6: 2026-09-06 | J6: =SUMIF(Motion!$E$3:$E$32,$A6,Motion!$B$3:$B$32)+SUMIF(Vision!$E$3:$E$17,$A6,Vision!$B$3:$B$17)+SUMIF(Odometry!$E$3:$E$15,$A6,Odometry!$B$3:$B$15) -> 13 | K6: =J6*Summary!$B$5 -> 65 | L6: =IF(F6<K6,"SHORT",IF(F6<Summary!$B$8,"Thin","OK")) -> OK | M6: https://jlcpcb.com/partdetail/C15850
A7: C1653 | B7: CL10C220JB8NNNC | C7: Samsung | D7: 22pF 50V C0G 0603 ±5% Multilayer Ceramic Capacitors MLCC - SMD/SMT | E7: Basic | F7: 2640152 | G7: 0.0068 | H7: No | I7: 2026-09-07 | J7: =SUMIF(Motion!$E$3:$E$32,$A7,Motion!$B$3:$B$32)+SUMIF(Vision!$E$3:$E$17,$A7,Vision!$B$3:$B$17)+SUMIF(Odometry!$E$3:$E$15,$A7,Odometry!$B$3:$B$15) -> 2 | K7: =J7*Summary!$B$5 -> 10 | L7: =IF(F7<K7,"SHORT",IF(F7<Summary!$B$8,"Thin","OK")) -> OK | M7: https://jlcpcb.com/partdetail/C1653
A8: C19666 | B8: CL10A475KO8NNNC | C8: Samsung | D8: 16V 4.7uF X5R ±10% 0603 Multilayer Ceramic Capacitors MLCC - SMD/SMT ROHS | E8: Basic | F8: 4016851 | G8: 0.0333 | H8: No | I8: 2026-09-06 | J8: =SUMIF(Motion!$E$3:$E$32,$A8,Motion!$B$3:$B$32)+SUMIF(Vision!$E$3:$E$17,$A8,Vision!$B$3:$B$17)+SUMIF(Odometry!$E$3:$E$15,$A8,Odometry!$B$3:$B$15) -> 1 | K8: =J8*Summary!$B$5 -> 5 | L8: =IF(F8<K8,"SHORT",IF(F8<Summary!$B$8,"Thin","OK")) -> OK | M8: https://jlcpcb.com/partdetail/C19666
A9: C20627123 | B9: 1812L300/24GR | C9: LUTE | D9: -40℃~+85℃ 1.4W 1.5mm 10mΩ 24V 3.41mm 3A 4.73mm 40A 4s 5A 60mΩ 1812 Resettable Fuses ROHS | E9: Extended | F9: 53558 | G9: 0.1384 | H9: No | I9: 2026-09-06 | J9: =SUMIF(Motion!$E$3:$E$32,$A9,Motion!$B$3:$B$32)+SUMIF(Vision!$E$3:$E$17,$A9,Vision!$B$3:$B$17)+SUMIF(Odometry!$E$3:$E$15,$A9,Odometry!$B$3:$B$15) -> 1 | K9: =J9*Summary!$B$5 -> 5 | L9: =IF(F9<K9,"SHORT",IF(F9<Summary!$B$8,"Thin","OK")) -> OK | M9: https://jlcpcb.com/partdetail/C20627123
A10: C25076 | B10: 0402WGF1000TCE | C10: UNI-ROYAL | D10: -55℃~+155℃ 100Ω 50V 62.5mW Thick Film Resistor ±1% ±100ppm/℃ 0402 Chip Resistor - Surface Mount ROHS | E10: Basic | F10: 3999877 | G10: 0.0037 | H10: No | I10: 2026-09-06 | J10: =SUMIF(Motion!$E$3:$E$32,$A10,Motion!$B$3:$B$32)+SUMIF(Vision!$E$3:$E$17,$A10,Vision!$B$3:$B$17)+SUMIF(Odometry!$E$3:$E$15,$A10,Odometry!$B$3:$B$15) -> 1 | K10: =J10*Summary!$B$5 -> 5 | L10: =IF(F10<K10,"SHORT",IF(F10<Summary!$B$8,"Thin","OK")) -> OK | M10: https://jlcpcb.com/partdetail/C25076
A11: C25105 | B11: 0402WGF330JTCE | C11: UNI-ROYAL | D11: 33Ω 62.5mW 0402 ±1% Chip Resistor - Surface Mount | E11: Basic | F11: 2403330 | G11: 0.0041 | H11: No | I11: 2026-09-07 | J11: =SUMIF(Motion!$E$3:$E$32,$A11,Motion!$B$3:$B$32)+SUMIF(Vision!$E$3:$E$17,$A11,Vision!$B$3:$B$17)+SUMIF(Odometry!$E$3:$E$15,$A11,Odometry!$B$3:$B$15) -> 1 | K11: =J11*Summary!$B$5 -> 5 | L11: =IF(F11<K11,"SHORT",IF(F11<Summary!$B$8,"Thin","OK")) -> OK | M11: https://jlcpcb.com/partdetail/C25105
A12: C25741 | B12: 0402WGF1003TCE | C12: UNI-ROYAL | D12: -55℃~+155℃ 100kΩ 50V 62.5mW Thick Film Resistor ±1% ±100ppm/℃ 0402 Chip Resistor - Surface Mount ROHS | E12: Basic | F12: 12874055 | G12: 0.0028 | H12: No | I12: 2026-09-06 | J12: =SUMIF(Motion!$E$3:$E$32,$A12,Motion!$B$3:$B$32)+SUMIF(Vision!$E$3:$E$17,$A12,Vision!$B$3:$B$17)+SUMIF(Odometry!$E$3:$E$15,$A12,Odometry!$B$3:$B$15) -> 3 | K12: =J12*Summary!$B$5 -> 15 | L12: =IF(F12<K12,"SHORT",IF(F12<Summary!$B$8,"Thin","OK")) -> OK | M12: https://jlcpcb.com/partdetail/C25741
A13: C25744 | B13: 0402WGF1002TCE | C13: UNI-ROYAL | D13: -55℃~+155℃ 10kΩ 50V 62.5mW Thick Film Resistor ±1% ±100ppm/℃ 0402 Chip Resistor - Surface Mount ROHS | E13: Basic | F13: 30863902 | G13: 0.0031 | H13: No | I13: 2026-09-06 | J13: =SUMIF(Motion!$E$3:$E$32,$A13,Motion!$B$3:$B$32)+SUMIF(Vision!$E$3:$E$17,$A13,Vision!$B$3:$B$17)+SUMIF(Odometry!$E$3:$E$15,$A13,Odometry!$B$3:$B$15) -> 10 | K13: =J13*Summary!$B$5 -> 50 | L13: =IF(F13<K13,"SHORT",IF(F13<Summary!$B$8,"Thin","OK")) -> OK | M13: https://jlcpcb.com/partdetail/C25744
A14: C25760 | B14: 0402WGF1803TCE | C14: UNI-ROYAL | D14: -55℃~+155℃ 180kΩ 50V 62.5mW Thick Film Resistor ±1% ±100ppm/℃ 0402 Chip Resistor - Surface Mount ROH | E14: Extended | F14: 229024 | G14: 0.002 | H14: No | I14: 2026-09-06 | J14: =SUMIF(Motion!$E$3:$E$32,$A14,Motion!$B$3:$B$32)+SUMIF(Vision!$E$3:$E$17,$A14,Vision!$B$3:$B$17)+SUMIF(Odometry!$E$3:$E$15,$A14,Odometry!$B$3:$B$15) -> 1 | K14: =J14*Summary!$B$5 -> 5 | L14: =IF(F14<K14,"SHORT",IF(F14<Summary!$B$8,"Thin","OK")) -> OK | M14: https://jlcpcb.com/partdetail/C25760
... A44: C96343 | B44: AP2127K-ADJTRG1 | C44: Diodes Inc | D44: -40℃~+85℃ 1 300mA 300mV@(300mA) 45dB@(10kHz)、68dB@(100Hz) 60uA 60uVrms 800mV~5.5V 9V Adjustable Over | E44: Extended | F44: 50060 | G44: 0.1269 | H44: No | I44: 2026-09-06 | J44: =SUMIF(Motion!$E$3:$E$32,$A44,Motion!$B$3:$B$32)+SUMIF(Vision!$E$3:$E$17,$A44,Vision!$B$3:$B$17)+SUMIF(Odometry!$E$3:$E$15,$A44,Odometry!$B$3:$B$15) -> 1 | K44: =J44*Summary!$B$5 -> 5 | L44: =IF(F44<K44,"SHORT",IF(F44<Summary!$B$8,"Thin","OK")) -> OK | M44: https://www.diodes.com/assets/Datasheets/AP2127.pdf

Sheet Motion
A1: BugBot Motion Board BOM (per board). Refs and quantities from Motion_sch_netlist.xml; prices and stock via the Parts sheet.
A2: Refs | B2: Qty | C2: Value | D2: Footprint | E2: LCSC | F2: MPN | G2: Class | H2: Stock | I2: Unit price (USD) | J2: Line cost (USD) | K2: Source / status | L2: Stock status | M2: Datasheet
A3: C1, C2, C6, C8, C14, C16, C18, C20, C23 | B3: 9 | C3: 10u | D3: Capacitor_SMD:C_0805_2012Metric | E3: C15850 | F3: =INDEX(Parts!$B$3:$B$44,MATCH($E3,Parts!$A$3:$A$44,0)) -> CL21A106KAYNNNE | G3: =INDEX(Parts!$E$3:$E$44,MATCH($E3,Parts!$A$3:$A$44,0)) -> Basic | H3: =INDEX(Parts!$F$3:$F$44,MATCH($E3,Parts!$A$3:$A$44,0)) -> 7849987 | I3: =INDEX(Parts!$G$3:$G$44,MATCH($E3,Parts!$A$3:$A$44,0)) -> 0.0847 | J3: =B3*I3 -> 0.7623 | K3: =IF(INDEX(Parts!$H$3:$H$44,MATCH($E3,Parts!$A$3:$A$44,0))="No","JLC assembly","PRE-ORDER") -> JLC assembly | L3: =IF(H3<B3*Summary!$B$5,"SHORT",IF(H3<Summary!$B$8,"Thin","OK")) -> OK | M3: https://jlcpcb.com/partdetail/C15850
A4: C4 | B4: 1 | C4: 1u | D4: Capacitor_SMD:C_0402_1005Metric | E4: C52923 | F4: =INDEX(Parts!$B$3:$B$44,MATCH($E4,Parts!$A$3:$A$44,0)) -> CL05A105KA5NQNC | G4: =INDEX(Parts!$E$3:$E$44,MATCH($E4,Parts!$A$3:$A$44,0)) -> Basic | H4: =INDEX(Parts!$F$3:$F$44,MATCH($E4,Parts!$A$3:$A$44,0)) -> 10724896 | I4: =INDEX(Parts!$G$3:$G$44,MATCH($E4,Parts!$A$3:$A$44,0)) -> 0.0121 | J4: =B4*I4 -> 0.0121 | K4: =IF(INDEX(Parts!$H$3:$H$44,MATCH($E4,Parts!$A$3:$A$44,0))="No","JLC assembly","PRE-ORDER") -> JLC assembly | L4: =IF(H4<B4*Summary!$B$5,"SHORT",IF(H4<Summary!$B$8,"Thin","OK")) -> OK | M4: https://jlcpcb.com/partdetail/C52923
A5: C5, C9, C21, C22 | B5: 4 | C5: 22u | D5: Capacitor_SMD:C_0805_2012Metric | E5: C45783 | F5: =INDEX(Parts!$B$3:$B$44,MATCH($E5,Parts!$A$3:$A$44,0)) -> CL21A226MAQNNNE | G5: =INDEX(Parts!$E$3:$E$44,MATCH($E5,Parts!$A$3:$A$44,0)) -> Basic | H5: =INDEX(Parts!$F$3:$F$44,MATCH($E5,Parts!$A$3:$A$44,0)) -> 5276598 | I5: =INDEX(Parts!$G$3:$G$44,MATCH($E5,Parts!$A$3:$A$44,0)) -> 0.2492 | J5: =B5*I5 -> 0.9968 | K5: =IF(INDEX(Parts!$H$3:$H$44,MATCH($E5,Parts!$A$3:$A$44,0))="No","JLC assembly","PRE-ORDER") -> JLC assembly | L5: =IF(H5<B5*Summary!$B$5,"SHORT",IF(H5<Summary!$B$8,"Thin","OK")) -> OK | M5: https://jlcpcb.com/partdetail/C45783
A6: C7, C13, C15, C17, C19, C24 | B6: 6 | C6: 100n | D6: Capacitor_SMD:C_0402_1005Metric | E6: C1525 | F6: =INDEX(Parts!$B$3:$B$44,MATCH($E6,Parts!$A$3:$A$44,0)) -> CL05B104KO5NNNC | G6: =INDEX(Parts!$E$3:$E$44,MATCH($E6,Parts!$A$3:$A$44,0)) -> Basic | H6: =INDEX(Parts!$F$3:$F$44,MATCH($E6,Parts!$A$3:$A$44,0)) -> 37375769 | I6: =INDEX(Parts!$G$3:$G$44,MATCH($E6,Parts!$A$3:$A$44,0)) -> 0.0051 | J6: =B6*I6 -> 0.0306 | K6: =IF(INDEX(Parts!$H$3:$H$44,MATCH($E6,Parts!$A$3:$A$44,0))="No","JLC assembly","PRE-ORDER") -> JLC assembly | L6: =IF(H6<B6*Summary!$B$5,"SHORT",IF(H6<Summary!$B$8,"Thin","OK")) -> OK | M6: https://jlcpcb.com/partdetail/C1525
A7: CB1 | B7: 1 | C7: 100u | D7: Capacitor_Tantalum_SMD:CP_EIA-3528-21_Kemet-B | E7: C7196 | F7: =INDEX(Parts!$B$3:$B$44,MATCH($E7,Parts!$A$3:$A$44,0)) -> TAJB107M010RNJ | G7: =INDEX(Parts!$E$3:$E$44,MATCH($E7,Parts!$A$3:$A$44,0)) -> Extended | H7: =INDEX(Parts!$F$3:$F$44,MATCH($E7,Parts!$A$3:$A$44,0)) -> 147504 | I7: =INDEX(Parts!$G$3:$G$44,MATCH($E7,Parts!$A$3:$A$44,0)) -> 0.4874 | J7: =B7*I7 -> 0.4874 | K7: =IF(INDEX(Parts!$H$3:$H$44,MATCH($E7,Parts!$A$3:$A$44,0))="No","JLC assembly","PRE-ORDER") -> JLC assembly | L7: =IF(H7<B7*Summary!$B$5,"SHORT",IF(H7<Summary!$B$8,"Thin","OK")) -> OK | M7: https://jlcpcb.com/partdetail/C7196
A8: F1 | B8: 1 | C8: 3A/6A PTC | D8: Fuse:Fuse_1812_4532Metric | E8: C20627123 | F8: =INDEX(Parts!$B$3:$B$44,MATCH($E8,Parts!$A$3:$A$44,0)) -> 1812L300/24GR | G8: =INDEX(Parts!$E$3:$E$44,MATCH($E8,Parts!$A$3:$A$44,0)) -> Extended | H8: =INDEX(Parts!$F$3:$F$44,MATCH($E8,Parts!$A$3:$A$44,0)) -> 53558 | I8: =INDEX(Parts!$G$3:$G$44,MATCH($E8,Parts!$A$3:$A$44,0)) -> 0.1384 | J8: =B8*I8 -> 0.1384 | K8: =IF(INDEX(Parts!$H$3:$H$44,MATCH($E8,Parts!$A$3:$A$44,0))="No","JLC assembly","PRE-ORDER") -> JLC assembly | L8: =IF(H8<B8*Summary!$B$5,"SHORT",IF(H8<Summary!$B$8,"Thin","OK")) -> OK | M8: https://jlcpcb.com/partdetail/C20627123
A9: J1 | B9: 1 | C9: USB-C 16P | D9: jlc:USB-C-SMD_TYPE-C-16PIN-2MD-073 | E9: C2765186 | F9: =INDEX(Parts!$B$3:$B$44,MATCH($E9,Parts!$A$3:$A$44,0)) -> TYPE-C 16PIN 2MD(073) | G9: =INDEX(Parts!$E$3:$E$44,MATCH($E9,Parts!$A$3:$A$44,0)) -> Extended | H9: =INDEX(Parts!$F$3:$F$44,MATCH($E9,Parts!$A$3:$A$44,0)) -> 995015 | I9: =INDEX(Parts!$G$3:$G$44,MATCH($E9,Parts!$A$3:$A$44,0)) -> 0.0743 | J9: =B9*I9 -> 0.0743 | K9: =IF(INDEX(Parts!$H$3:$H$44,MATCH($E9,Parts!$A$3:$A$44,0))="No","JLC assembly","PRE-ORDER") -> JLC assembly | L9: =IF(H9<B9*Summary!$B$5,"SHORT",IF(H9<Summary!$B$8,"Thin","OK")) -> OK | M9: https://jlcpcb.com/partdetail/C2765186
A10: J2 | B10: 1 | C10: JST-PH 2P batt | D10: jlc:CONN-SMD_P2.00_S2B-PH-SM4-TB-LF-SN | E10: C295747 | F10: =INDEX(Parts!$B$3:$B$44,MATCH($E10,Parts!$A$3:$A$44,0)) -> S2B-PH-SM4-TB(LF)(SN) | G10: =INDEX(Parts!$E$3:$E$44,MATCH($E10,Parts!$A$3:$A$44,0)) -> Extended | H10: =INDEX(Parts!$F$3:$F$44,MATCH($E10,Parts!$A$3:$A$44,0)) -> 29773 | I10: =INDEX(Parts!$G$3:$G$44,MATCH($E10,Parts!$A$3:$A$44,0)) -> 0.2396 | J10: =B10*I10 -> 0.2396 | K10: =IF(INDEX(Parts!$H$3:$H$44,MATCH($E10,Parts!$A$3:$A$44,0))="No","JLC assembly","PRE-ORDER") -> JLC assembly | L10: =IF(H10<B10*Summary!$B$5,"SHORT",IF(H10<Summary!$B$8,"Thin","OK")) -> OK | M10: https://jlcpcb.com/partdetail/C295747
A11: J3, J4, J5, J6 | B11: 4 | C11: Motor A GH2 | D11: Connector_JST:JST_GH_BM02B-GHS-TBT_1x02-1MP_P1.25mm_Vertical | E11: C3029368 | F11: =INDEX(Parts!$B$3:$B$44,MATCH($E11,Parts!$A$3:$A$44,0)) -> WAFER-GH1.25-2PLB | G11: =INDEX(Parts!$E$3:$E$44,MATCH($E11,Parts!$A$3:$A$44,0)) -> Extended | H11: =INDEX(Parts!$F$3:$F$44,MATCH($E11,Parts!$A$3:$A$44,0)) -> 46600 | I11: =INDEX(Parts!$G$3:$G$44,MATCH($E11,Parts!$A$3:$A$44,0)) -> 0.13 | J11: =B11*I11 -> 0.52 | K11: =IF(INDEX(Parts!$H$3:$H$44,MATCH($E11,Parts!$A$3:$A$44,0))="No","JLC assembly","PRE-ORDER") -> JLC assembly | L11: =IF(H11<B11*Summary!$B$5,"SHORT",IF(H11<Summary!$B$8,"Thin","OK")) -> OK | M11: https://jlcpcb.com/partdetail/C3029368
A12: J7 | B12: 1 | C12: Optical flow + IMU GH10 | D12: Connector_JST:JST_GH_BM10B-GHS-TBT_1x10-1MP_P1.25mm_Vertical | E12: C3029376 | F12: =INDEX(Parts!$B$3:$B$44,MATCH($E12,Parts!$A$3:$A$44,0)) -> WAFER-GH1.25-10PLB | G12: =INDEX(Parts!$E$3:$E$44,MATCH($E12,Parts!$A$3:$A$44,0)) -> Extended | H12: =INDEX(Parts!$F$3:$F$44,MATCH($E12,Parts!$A$3:$A$44,0)) -> 1796 | I12: =INDEX(Parts!$G$3:$G$44,MATCH($E12,Parts!$A$3:$A$44,0)) -> 0.2164 | J12: =B12*I12 -> 0.2164 | K12: =IF(INDEX(Parts!$H$3:$H$44,MATCH($E12,Parts!$A$3:$A$44,0))="No","JLC assembly","PRE-ORDER") -> JLC assembly | L12: =IF(H12<B12*Summary!$B$5,"SHORT",IF(H12<Summary!$B$8,"Thin","OK")) -> Thin | M12: https://jlcpcb.com/partdetail/C3029376
A13: J10, J11 | B13: 2 | C13: Servo 1 GH1.25 3P side-entry | D13: Connector_JST:JST_GH_SM03B-GHS-TB_1x03-1MP_P1.25mm_Horizontal | E13: C3029378 | F13: =INDEX(Parts!$B$3:$B$44,MATCH($E13,Parts!$A$3:$A$44,0)) -> WAFER-GH1.25-3PWB | G13: =INDEX(Parts!$E$3:$E$44,MATCH($E13,Parts!$A$3:$A$44,0)) -> Extended | H13: =INDEX(Parts!$F$3:$F$44,MATCH($E13,Parts!$A$3:$A$44,0)) -> 78982 | I13: =INDEX(Parts!$G$3:$G$44,MATCH($E13,Parts!$A$3:$A$44,0)) -> 0.1243 | J13: =B13*I13 -> 0.2486 | K13: =IF(INDEX(Parts!$H$3:$H$44,MATCH($E13,Parts!$A$3:$A$44,0))="No","JLC assembly","PRE-ORDER") -> JLC assembly | L13: =IF(H13<B13*Summary!$B$5,"SHORT",IF(H13<Summary!$B$8,"Thin","OK")) -> OK | M13: https://jlcpcb.com/partdetail/C3029378
A14: L1 | B14: 1 | C14: 1uH 4.5A | D14: Inductor_SMD:L_1008_2520Metric | E14: C5832356 | F14: =INDEX(Parts!$B$3:$B$44,MATCH($E14,Parts!$A$3:$A$44,0)) -> FTC252010S1R0MBCA | G14: =INDEX(Parts!$E$3:$E$44,MATCH($E14,Parts!$A$3:$A$44,0)) -> Extended | H14: =INDEX(Parts!$F$3:$F$44,MATCH($E14,Parts!$A$3:$A$44,0)) -> 263367 | I14: =INDEX(Parts!$G$3:$G$44,MATCH($E14,Parts!$A$3:$A$44,0)) -> 0.0278 | J14: =B14*I14 -> 0.0278 | K14: =IF(INDEX(Parts!$H$3:$H$44,MATCH($E14,Parts!$A$3:$A$44,0))="No","JLC assembly","PRE-ORDER") -> JLC assembly | L14: =IF(H14<B14*Summary!$B$5,"SHORT",IF(H14<Summary!$B$8,"Thin","OK")) -> OK | M14: https://jlcpcb.com/partdetail/C5832356
... A30: U6, U7, U8, U9 | B30: 4 | C30: DRV8830DGQR | D30: Package_SO:MSOP-10-1EP_3x3mm_P0.5mm_EP1.68x1.88mm | E30: C127591 | F30: =INDEX(Parts!$B$3:$B$44,MATCH($E30,Parts!$A$3:$A$44,0)) -> DRV8830DGQR | G30: =INDEX(Parts!$E$3:$E$44,MATCH($E30,Parts!$A$3:$A$44,0)) -> Extended | H30: =INDEX(Parts!$F$3:$F$44,MATCH($E30,Parts!$A$3:$A$44,0)) -> 129 | I30: =INDEX(Parts!$G$3:$G$44,MATCH($E30,Parts!$A$3:$A$44,0)) -> 2.7355 | J30: =B30*I30 -> 10.942 | K30: =IF(INDEX(Parts!$H$3:$H$44,MATCH($E30,Parts!$A$3:$A$44,0))="No","JLC assembly","PRE-ORDER") -> JLC assembly | L30: =IF(H30<B30*Summary!$B$5,"SHORT",IF(H30<Summary!$B$8,"Thin","OK")) -> Thin | M30: https://www.ti.com/lit/ds/symlink/drv8830.pdf
A31: J8 | B31: 1 | C31: Stack A 2x5 socket | D31: Connector_PinSocket_2.00mm:PinSocket_2x05_P2.00mm_Vertical | I31: 0 | J31: =B31*I31 -> 0 | K31: 2x5 2.00 mm socket, hand-soldered (AliExpress/Farnell) | L31: n/a
A32: J9 | B32: 1 | C32: Stack B 2x5 socket | D32: Connector_PinSocket_2.00mm:PinSocket_2x05_P2.00mm_Vertical | I32: 0 | J32: =B32*I32 -> 0 | K32: 2x5 2.00 mm socket, hand-soldered (AliExpress/Farnell) | L32: n/a
A34: Totals per board | B34: =SUM(B3:B32) -> 63 | J34: =SUM(J3:J32) -> 16.6321
A35: Extended-part lines (one-off fee each per order) | B35: =COUNTIF(G3:G32,"Extended") -> 18
A36: Lines with no JLC code (hand-soldered) | B36: =COUNTBLANK(E3:E32) -> 2
A37: Lines below thin-stock threshold | B37: =COUNTIF(L3:L32,"Thin")+COUNTIF(L3:L32,"SHORT") -> 3
A38: Lines short for the planned run | B38: =COUNTIF(L3:L32,"SHORT") -> 0

Sheet Vision
A1: BugBot Vision Board BOM (per board). Refs and quantities from Vision_sch_netlist.xml; prices and stock via the Parts sheet.
A2: Refs | B2: Qty | C2: Value | D2: Footprint | E2: LCSC | F2: MPN | G2: Class | H2: Stock | I2: Unit price (USD) | J2: Line cost (USD) | K2: Source / status | L2: Stock status | M2: Datasheet
A3: C1 | B3: 1 | C3: 22u | D3: Capacitor_SMD:C_0805_2012Metric | E3: C45783 | F3: =INDEX(Parts!$B$3:$B$44,MATCH($E3,Parts!$A$3:$A$44,0)) -> CL21A226MAQNNNE | G3: =INDEX(Parts!$E$3:$E$44,MATCH($E3,Parts!$A$3:$A$44,0)) -> Basic | H3: =INDEX(Parts!$F$3:$F$44,MATCH($E3,Parts!$A$3:$A$44,0)) -> 5276598 | I3: =INDEX(Parts!$G$3:$G$44,MATCH($E3,Parts!$A$3:$A$44,0)) -> 0.2492 | J3: =B3*I3 -> 0.2492 | K3: =IF(INDEX(Parts!$H$3:$H$44,MATCH($E3,Parts!$A$3:$A$44,0))="No","JLC assembly","PRE-ORDER") -> JLC assembly | L3: =IF(H3<B3*Summary!$B$5,"SHORT",IF(H3<Summary!$B$8,"Thin","OK")) -> OK | M3: https://jlcpcb.com/partdetail/C45783
A4: C2, C20, C43, C54 | B4: 4 | C4: 10u | D4: Capacitor_SMD:C_0805_2012Metric | E4: C15850 | F4: =INDEX(Parts!$B$3:$B$44,MATCH($E4,Parts!$A$3:$A$44,0)) -> CL21A106KAYNNNE | G4: =INDEX(Parts!$E$3:$E$44,MATCH($E4,Parts!$A$3:$A$44,0)) -> Basic | H4: =INDEX(Parts!$F$3:$F$44,MATCH($E4,Parts!$A$3:$A$44,0)) -> 7849987 | I4: =INDEX(Parts!$G$3:$G$44,MATCH($E4,Parts!$A$3:$A$44,0)) -> 0.0847 | J4: =B4*I4 -> 0.3388 | K4: =IF(INDEX(Parts!$H$3:$H$44,MATCH($E4,Parts!$A$3:$A$44,0))="No","JLC assembly","PRE-ORDER") -> JLC assembly | L4: =IF(H4<B4*Summary!$B$5,"SHORT",IF(H4<Summary!$B$8,"Thin","OK")) -> OK | M4: https://jlcpcb.com/partdetail/C15850
A5: C6, C21, C42, C44, C55 | B5: 5 | C5: 100n | D5: Capacitor_SMD:C_0402_1005Metric | E5: C1525 | F5: =INDEX(Parts!$B$3:$B$44,MATCH($E5,Parts!$A$3:$A$44,0)) -> CL05B104KO5NNNC | G5: =INDEX(Parts!$E$3:$E$44,MATCH($E5,Parts!$A$3:$A$44,0)) -> Basic | H5: =INDEX(Parts!$F$3:$F$44,MATCH($E5,Parts!$A$3:$A$44,0)) -> 37375769 | I5: =INDEX(Parts!$G$3:$G$44,MATCH($E5,Parts!$A$3:$A$44,0)) -> 0.0051 | J5: =B5*I5 -> 0.0255 | K5: =IF(INDEX(Parts!$H$3:$H$44,MATCH($E5,Parts!$A$3:$A$44,0))="No","JLC assembly","PRE-ORDER") -> JLC assembly | L5: =IF(H5<B5*Summary!$B$5,"SHORT",IF(H5<Summary!$B$8,"Thin","OK")) -> OK | M5: https://jlcpcb.com/partdetail/C1525
A6: C14 | B6: 1 | C6: 1u | D6: Capacitor_SMD:C_0402_1005Metric | E6: C52923 | F6: =INDEX(Parts!$B$3:$B$44,MATCH($E6,Parts!$A$3:$A$44,0)) -> CL05A105KA5NQNC | G6: =INDEX(Parts!$E$3:$E$44,MATCH($E6,Parts!$A$3:$A$44,0)) -> Basic | H6: =INDEX(Parts!$F$3:$F$44,MATCH($E6,Parts!$A$3:$A$44,0)) -> 10724896 | I6: =INDEX(Parts!$G$3:$G$44,MATCH($E6,Parts!$A$3:$A$44,0)) -> 0.0121 | J6: =B6*I6 -> 0.0121 | K6: =IF(INDEX(Parts!$H$3:$H$44,MATCH($E6,Parts!$A$3:$A$44,0))="No","JLC assembly","PRE-ORDER") -> JLC assembly | L6: =IF(H6<B6*Summary!$B$5,"SHORT",IF(H6<Summary!$B$8,"Thin","OK")) -> OK | M6: https://jlcpcb.com/partdetail/C52923
A7: J3 | B7: 1 | C7: Camera FPC 22P 0.5mm top-contact OV5647 spy (pin k = Pi Zero pin 23-k) | D7: jlc:FPC-SMD_22P-P0.50_HDGC_0.5K-AS-22PWB | E7: C2911765 | F7: =INDEX(Parts!$B$3:$B$44,MATCH($E7,Parts!$A$3:$A$44,0)) -> 0.5K-AS-22PWB | G7: =INDEX(Parts!$E$3:$E$44,MATCH($E7,Parts!$A$3:$A$44,0)) -> Extended | H7: =INDEX(Parts!$F$3:$F$44,MATCH($E7,Parts!$A$3:$A$44,0)) -> 473 | I7: =INDEX(Parts!$G$3:$G$44,MATCH($E7,Parts!$A$3:$A$44,0)) -> 0.1355 | J7: =B7*I7 -> 0.1355 | K7: =IF(INDEX(Parts!$H$3:$H$44,MATCH($E7,Parts!$A$3:$A$44,0))="No","JLC assembly","PRE-ORDER") -> JLC assembly | L7: =IF(H7<B7*Summary!$B$5,"SHORT",IF(H7<Summary!$B$8,"Thin","OK")) -> Thin | M7: https://jlcpcb.com/partdetail/C2911765
A8: J7 | B8: 1 | C8: ToF GH1.25 6P side-entry (underside) | D8: Connector_JST:JST_GH_SM06B-GHS-TB_1x06-1MP_P1.25mm_Horizontal | E8: C3029381 | F8: =INDEX(Parts!$B$3:$B$44,MATCH($E8,Parts!$A$3:$A$44,0)) -> WAFER-GH1.25-6PWB | G8: =INDEX(Parts!$E$3:$E$44,MATCH($E8,Parts!$A$3:$A$44,0)) -> Extended | H8: =INDEX(Parts!$F$3:$F$44,MATCH($E8,Parts!$A$3:$A$44,0)) -> 32531 | I8: =INDEX(Parts!$G$3:$G$44,MATCH($E8,Parts!$A$3:$A$44,0)) -> 0.1605 | J8: =B8*I8 -> 0.1605 | K8: =IF(INDEX(Parts!$H$3:$H$44,MATCH($E8,Parts!$A$3:$A$44,0))="No","JLC assembly","PRE-ORDER") -> JLC assembly | L8: =IF(H8<B8*Summary!$B$5,"SHORT",IF(H8<Summary!$B$8,"Thin","OK")) -> OK | M8: https://jlcpcb.com/partdetail/C3029381
A9: J10 | B9: 1 | C9: LED GH1.25 3P (WS2812 in the ball) | D9: jlc:CONN-SMD_3P-P1.25_XUNPU_WAFER-GH1.25-3PLB | E9: C3029369 | F9: =INDEX(Parts!$B$3:$B$44,MATCH($E9,Parts!$A$3:$A$44,0)) -> WAFER-GH1.25-3PLB | G9: =INDEX(Parts!$E$3:$E$44,MATCH($E9,Parts!$A$3:$A$44,0)) -> Extended | H9: =INDEX(Parts!$F$3:$F$44,MATCH($E9,Parts!$A$3:$A$44,0)) -> 15257 | I9: =INDEX(Parts!$G$3:$G$44,MATCH($E9,Parts!$A$3:$A$44,0)) -> 0.1467 | J9: =B9*I9 -> 0.1467 | K9: =IF(INDEX(Parts!$H$3:$H$44,MATCH($E9,Parts!$A$3:$A$44,0))="No","JLC assembly","PRE-ORDER") -> JLC assembly | L9: =IF(H9<B9*Summary!$B$5,"SHORT",IF(H9<Summary!$B$8,"Thin","OK")) -> OK | M9: https://jlcpcb.com/partdetail/C3029369
A10: R7, R8, R9, R14 | B10: 4 | C10: 10k | D10: Resistor_SMD:R_0402_1005Metric | E10: C25744 | F10: =INDEX(Parts!$B$3:$B$44,MATCH($E10,Parts!$A$3:$A$44,0)) -> 0402WGF1002TCE | G10: =INDEX(Parts!$E$3:$E$44,MATCH($E10,Parts!$A$3:$A$44,0)) -> Basic | H10: =INDEX(Parts!$F$3:$F$44,MATCH($E10,Parts!$A$3:$A$44,0)) -> 30863902 | I10: =INDEX(Parts!$G$3:$G$44,MATCH($E10,Parts!$A$3:$A$44,0)) -> 0.0031 | J10: =B10*I10 -> 0.0124 | K10: =IF(INDEX(Parts!$H$3:$H$44,MATCH($E10,Parts!$A$3:$A$44,0))="No","JLC assembly","PRE-ORDER") -> JLC assembly | L10: =IF(H10<B10*Summary!$B$5,"SHORT",IF(H10<Summary!$B$8,"Thin","OK")) -> OK | M10: https://jlcpcb.com/partdetail/C25744
A11: R11, R12 | B11: 2 | C11: 2.2k | D11: Resistor_SMD:R_0402_1005Metric | E11: C25879 | F11: =INDEX(Parts!$B$3:$B$44,MATCH($E11,Parts!$A$3:$A$44,0)) -> 0402WGF2201TCE | G11: =INDEX(Parts!$E$3:$E$44,MATCH($E11,Parts!$A$3:$A$44,0)) -> Basic | H11: =INDEX(Parts!$F$3:$F$44,MATCH($E11,Parts!$A$3:$A$44,0)) -> 1612344 | I11: =INDEX(Parts!$G$3:$G$44,MATCH($E11,Parts!$A$3:$A$44,0)) -> 0.0039 | J11: =B11*I11 -> 0.0078 | K11: =IF(INDEX(Parts!$H$3:$H$44,MATCH($E11,Parts!$A$3:$A$44,0))="No","JLC assembly","PRE-ORDER") -> JLC assembly | L11: =IF(H11<B11*Summary!$B$5,"SHORT",IF(H11<Summary!$B$8,"Thin","OK")) -> OK | M11: https://jlcpcb.com/partdetail/C25879
A12: R13 | B12: 1 | C12: 100R | D12: Resistor_SMD:R_0402_1005Metric | E12: C25076 | F12: =INDEX(Parts!$B$3:$B$44,MATCH($E12,Parts!$A$3:$A$44,0)) -> 0402WGF1000TCE | G12: =INDEX(Parts!$E$3:$E$44,MATCH($E12,Parts!$A$3:$A$44,0)) -> Basic | H12: =INDEX(Parts!$F$3:$F$44,MATCH($E12,Parts!$A$3:$A$44,0)) -> 3999877 | I12: =INDEX(Parts!$G$3:$G$44,MATCH($E12,Parts!$A$3:$A$44,0)) -> 0.0037 | J12: =B12*I12 -> 0.0037 | K12: =IF(INDEX(Parts!$H$3:$H$44,MATCH($E12,Parts!$A$3:$A$44,0))="No","JLC assembly","PRE-ORDER") -> JLC assembly | L12: =IF(H12<B12*Summary!$B$5,"SHORT",IF(H12<Summary!$B$8,"Thin","OK")) -> OK | M12: https://jlcpcb.com/partdetail/C25076
A13: SW1, SW2 | B13: 2 | C13: ZX-QC4545-4.3TP | D13: jlc:KEY-SMD_4P-L4.5-W4.5-P3.00-LS6.9 | E13: C7470171 | F13: =INDEX(Parts!$B$3:$B$44,MATCH($E13,Parts!$A$3:$A$44,0)) -> ZX-QC4545-4.3TP | G13: =INDEX(Parts!$E$3:$E$44,MATCH($E13,Parts!$A$3:$A$44,0)) -> Extended | H13: =INDEX(Parts!$F$3:$F$44,MATCH($E13,Parts!$A$3:$A$44,0)) -> 25261 | I13: =INDEX(Parts!$G$3:$G$44,MATCH($E13,Parts!$A$3:$A$44,0)) -> 0.0251 | J13: =B13*I13 -> 0.0502 | K13: =IF(INDEX(Parts!$H$3:$H$44,MATCH($E13,Parts!$A$3:$A$44,0))="No","JLC assembly","PRE-ORDER") -> JLC assembly | L13: =IF(H13<B13*Summary!$B$5,"SHORT",IF(H13<Summary!$B$8,"Thin","OK")) -> OK | M13: https://jlcpcb.com/partdetail/C7470171
A14: SW3 | B14: 1 | C14: MSK12C02 | D14: jlc:SW-TH_MSK12C02 | E14: C431540 | F14: =INDEX(Parts!$B$3:$B$44,MATCH($E14,Parts!$A$3:$A$44,0)) -> MSK12C02 | G14: =INDEX(Parts!$E$3:$E$44,MATCH($E14,Parts!$A$3:$A$44,0)) -> Extended | H14: =INDEX(Parts!$F$3:$F$44,MATCH($E14,Parts!$A$3:$A$44,0)) -> 150031 | I14: =INDEX(Parts!$G$3:$G$44,MATCH($E14,Parts!$A$3:$A$44,0)) -> 0.0566 | J14: =B14*I14 -> 0.0566 | K14: =IF(INDEX(Parts!$H$3:$H$44,MATCH($E14,Parts!$A$3:$A$44,0))="No","JLC assembly","PRE-ORDER") -> JLC assembly | L14: =IF(H14<B14*Summary!$B$5,"SHORT",IF(H14<Summary!$B$8,"Thin","OK")) -> OK | M14: https://jlcpcb.com/partdetail/C431540
A15: J8 | B15: 1 | C15: Stack A 2x5 (mates Motion J8) | D15: Connector_PinHeader_2.00mm:PinHeader_2x05_P2.00mm_Vertical | I15: 0 | J15: =B15*I15 -> 0 | K15: 2x5 2.00 mm pin header, hand-soldered | L15: n/a
A16: J9 | B16: 1 | C16: Stack B 2x5 (mates Motion J9) | D16: Connector_PinHeader_2.00mm:PinHeader_2x05_P2.00mm_Vertical | I16: 0 | J16: =B16*I16 -> 0 | K16: 2x5 2.00 mm pin header, hand-soldered | L16: n/a
A17: U3 | B17: 1 | C17: ESP32-P4-Module | D17: jlc:ESP32-P4-Module | I17: 0 | J17: =B17*I17 -> 0 | K17: ESP32-P4 + C6 core module (Waveshare), hand-soldered | L17: n/a | M17: https://www.waveshare.com/wiki/ESP32-P4-Module
A19: Totals per board | B19: =SUM(B3:B17) -> 27 | J19: =SUM(J3:J17) -> 1.199
A20: Extended-part lines (one-off fee each per order) | B20: =COUNTIF(G3:G17,"Extended") -> 5
A21: Lines with no JLC code (hand-soldered) | B21: =COUNTBLANK(E3:E17) -> 3
A22: Lines below thin-stock threshold | B22: =COUNTIF(L3:L17,"Thin")+COUNTIF(L3:L17,"SHORT") -> 1
A23: Lines short for the planned run | B23: =COUNTIF(L3:L17,"SHORT") -> 0

Sheet Odometry
A1: BugBot Odometry Board BOM (per board). Refs and quantities from Odometry_sch_netlist.xml; prices and stock via the Parts sheet.
A2: Refs | B2: Qty | C2: Value | D2: Footprint | E2: LCSC | F2: MPN | G2: Class | H2: Stock | I2: Unit price (USD) | J2: Line cost (USD) | K2: Source / status | L2: Stock status | M2: Datasheet
A3: C1, C2, C3, C4, C9 | B3: 5 | C3: 1u | D3: Capacitor_SMD:C_0402_1005Metric | E3: C52923 | F3: =INDEX(Parts!$B$3:$B$44,MATCH($E3,Parts!$A$3:$A$44,0)) -> CL05A105KA5NQNC | G3: =INDEX(Parts!$E$3:$E$44,MATCH($E3,Parts!$A$3:$A$44,0)) -> Basic | H3: =INDEX(Parts!$F$3:$F$44,MATCH($E3,Parts!$A$3:$A$44,0)) -> 10724896 | I3: =INDEX(Parts!$G$3:$G$44,MATCH($E3,Parts!$A$3:$A$44,0)) -> 0.0121 | J3: =B3*I3 -> 0.0605 | K3: =IF(INDEX(Parts!$H$3:$H$44,MATCH($E3,Parts!$A$3:$A$44,0))="No","JLC assembly","PRE-ORDER") -> JLC assembly | L3: =IF(H3<B3*Summary!$B$5,"SHORT",IF(H3<Summary!$B$8,"Thin","OK")) -> OK | M3: https://jlcpcb.com/partdetail/C52923
A4: C5 | B4: 1 | C4: 4.7u | D4: Capacitor_SMD:C_0603_1608Metric | E4: C19666 | F4: =INDEX(Parts!$B$3:$B$44,MATCH($E4,Parts!$A$3:$A$44,0)) -> CL10A475KO8NNNC | G4: =INDEX(Parts!$E$3:$E$44,MATCH($E4,Parts!$A$3:$A$44,0)) -> Basic | H4: =INDEX(Parts!$F$3:$F$44,MATCH($E4,Parts!$A$3:$A$44,0)) -> 4016851 | I4: =INDEX(Parts!$G$3:$G$44,MATCH($E4,Parts!$A$3:$A$44,0)) -> 0.0333 | J4: =B4*I4 -> 0.0333 | K4: =IF(INDEX(Parts!$H$3:$H$44,MATCH($E4,Parts!$A$3:$A$44,0))="No","JLC assembly","PRE-ORDER") -> JLC assembly | L4: =IF(H4<B4*Summary!$B$5,"SHORT",IF(H4<Summary!$B$8,"Thin","OK")) -> OK | M4: https://jlcpcb.com/partdetail/C19666
A5: C6, C7, C8 | B5: 3 | C5: 100n | D5: Capacitor_SMD:C_0402_1005Metric | E5: C1525 | F5: =INDEX(Parts!$B$3:$B$44,MATCH($E5,Parts!$A$3:$A$44,0)) -> CL05B104KO5NNNC | G5: =INDEX(Parts!$E$3:$E$44,MATCH($E5,Parts!$A$3:$A$44,0)) -> Basic | H5: =INDEX(Parts!$F$3:$F$44,MATCH($E5,Parts!$A$3:$A$44,0)) -> 37375769 | I5: =INDEX(Parts!$G$3:$G$44,MATCH($E5,Parts!$A$3:$A$44,0)) -> 0.0051 | J5: =B5*I5 -> 0.0153 | K5: =IF(INDEX(Parts!$H$3:$H$44,MATCH($E5,Parts!$A$3:$A$44,0))="No","JLC assembly","PRE-ORDER") -> JLC assembly | L5: =IF(H5<B5*Summary!$B$5,"SHORT",IF(H5<Summary!$B$8,"Thin","OK")) -> OK | M5: https://jlcpcb.com/partdetail/C1525
A6: C10, C11 | B6: 2 | C6: 22p | D6: Capacitor_SMD:C_0603_1608Metric | E6: C1653 | F6: =INDEX(Parts!$B$3:$B$44,MATCH($E6,Parts!$A$3:$A$44,0)) -> CL10C220JB8NNNC | G6: =INDEX(Parts!$E$3:$E$44,MATCH($E6,Parts!$A$3:$A$44,0)) -> Basic | H6: =INDEX(Parts!$F$3:$F$44,MATCH($E6,Parts!$A$3:$A$44,0)) -> 2640152 | I6: =INDEX(Parts!$G$3:$G$44,MATCH($E6,Parts!$A$3:$A$44,0)) -> 0.0068 | J6: =B6*I6 -> 0.0136 | K6: =IF(INDEX(Parts!$H$3:$H$44,MATCH($E6,Parts!$A$3:$A$44,0))="No","JLC assembly","PRE-ORDER") -> JLC assembly | L6: =IF(H6<B6*Summary!$B$5,"SHORT",IF(H6<Summary!$B$8,"Thin","OK")) -> OK | M6: https://jlcpcb.com/partdetail/C1653
A7: J1 | B7: 1 | C7: Odometry GH10 to Motion J7 | D7: Connector_JST:JST_GH_BM10B-GHS-TBT_1x10-1MP_P1.25mm_Vertical | E7: C3029376 | F7: =INDEX(Parts!$B$3:$B$44,MATCH($E7,Parts!$A$3:$A$44,0)) -> WAFER-GH1.25-10PLB | G7: =INDEX(Parts!$E$3:$E$44,MATCH($E7,Parts!$A$3:$A$44,0)) -> Extended | H7: =INDEX(Parts!$F$3:$F$44,MATCH($E7,Parts!$A$3:$A$44,0)) -> 1796 | I7: =INDEX(Parts!$G$3:$G$44,MATCH($E7,Parts!$A$3:$A$44,0)) -> 0.2164 | J7: =B7*I7 -> 0.2164 | K7: =IF(INDEX(Parts!$H$3:$H$44,MATCH($E7,Parts!$A$3:$A$44,0))="No","JLC assembly","PRE-ORDER") -> JLC assembly | L7: =IF(H7<B7*Summary!$B$5,"SHORT",IF(H7<Summary!$B$8,"Thin","OK")) -> Thin | M7: https://jlcpcb.com/partdetail/C3029376
A8: R1 | B8: 1 | C8: 47k | D8: Resistor_SMD:R_0402_1005Metric | E8: C25792 | F8: =INDEX(Parts!$B$3:$B$44,MATCH($E8,Parts!$A$3:$A$44,0)) -> 0402WGF4702TCE | G8: =INDEX(Parts!$E$3:$E$44,MATCH($E8,Parts!$A$3:$A$44,0)) -> Basic | H8: =INDEX(Parts!$F$3:$F$44,MATCH($E8,Parts!$A$3:$A$44,0)) -> 6406298 | I8: =INDEX(Parts!$G$3:$G$44,MATCH($E8,Parts!$A$3:$A$44,0)) -> 0.0029 | J8: =B8*I8 -> 0.0029 | K8: =IF(INDEX(Parts!$H$3:$H$44,MATCH($E8,Parts!$A$3:$A$44,0))="No","JLC assembly","PRE-ORDER") -> JLC assembly | L8: =IF(H8<B8*Summary!$B$5,"SHORT",IF(H8<Summary!$B$8,"Thin","OK")) -> OK | M8: https://jlcpcb.com/partdetail/C25792
A9: R2 | B9: 1 | C9: 33k | D9: Resistor_SMD:R_0402_1005Metric | E9: C25779 | F9: =INDEX(Parts!$B$3:$B$44,MATCH($E9,Parts!$A$3:$A$44,0)) -> 0402WGF3302TCE | G9: =INDEX(Parts!$E$3:$E$44,MATCH($E9,Parts!$A$3:$A$44,0)) -> Basic | H9: =INDEX(Parts!$F$3:$F$44,MATCH($E9,Parts!$A$3:$A$44,0)) -> 1512746 | I9: =INDEX(Parts!$G$3:$G$44,MATCH($E9,Parts!$A$3:$A$44,0)) -> 0.0092 | J9: =B9*I9 -> 0.0092 | K9: =IF(INDEX(Parts!$H$3:$H$44,MATCH($E9,Parts!$A$3:$A$44,0))="No","JLC assembly","PRE-ORDER") -> JLC assembly | L9: =IF(H9<B9*Summary!$B$5,"SHORT",IF(H9<Summary!$B$8,"Thin","OK")) -> OK | M9: https://jlcpcb.com/partdetail/C25779
A10: R3 | B10: 1 | C10: 33R | D10: Resistor_SMD:R_0402_1005Metric | E10: C25105 | F10: =INDEX(Parts!$B$3:$B$44,MATCH($E10,Parts!$A$3:$A$44,0)) -> 0402WGF330JTCE | G10: =INDEX(Parts!$E$3:$E$44,MATCH($E10,Parts!$A$3:$A$44,0)) -> Basic | H10: =INDEX(Parts!$F$3:$F$44,MATCH($E10,Parts!$A$3:$A$44,0)) -> 2403330 | I10: =INDEX(Parts!$G$3:$G$44,MATCH($E10,Parts!$A$3:$A$44,0)) -> 0.0041 | J10: =B10*I10 -> 0.0041 | K10: =IF(INDEX(Parts!$H$3:$H$44,MATCH($E10,Parts!$A$3:$A$44,0))="No","JLC assembly","PRE-ORDER") -> JLC assembly | L10: =IF(H10<B10*Summary!$B$5,"SHORT",IF(H10<Summary!$B$8,"Thin","OK")) -> OK | M10: https://jlcpcb.com/partdetail/C25105
A11: R4, R5, R6, R7 | B11: 4 | C11: 10k | D11: Resistor_SMD:R_0402_1005Metric | E11: C25744 | F11: =INDEX(Parts!$B$3:$B$44,MATCH($E11,Parts!$A$3:$A$44,0)) -> 0402WGF1002TCE | G11: =INDEX(Parts!$E$3:$E$44,MATCH($E11,Parts!$A$3:$A$44,0)) -> Basic | H11: =INDEX(Parts!$F$3:$F$44,MATCH($E11,Parts!$A$3:$A$44,0)) -> 30863902 | I11: =INDEX(Parts!$G$3:$G$44,MATCH($E11,Parts!$A$3:$A$44,0)) -> 0.0031 | J11: =B11*I11 -> 0.0124 | K11: =IF(INDEX(Parts!$H$3:$H$44,MATCH($E11,Parts!$A$3:$A$44,0))="No","JLC assembly","PRE-ORDER") -> JLC assembly | L11: =IF(H11<B11*Summary!$B$5,"SHORT",IF(H11<Summary!$B$8,"Thin","OK")) -> OK | M11: https://jlcpcb.com/partdetail/C25744
A12: U1 | B12: 1 | C12: AP2127K-ADJ | D12: jlc:SOT-23-5_L3.0-W1.7-P0.95-LS2.8-BR | E12: C96343 | F12: =INDEX(Parts!$B$3:$B$44,MATCH($E12,Parts!$A$3:$A$44,0)) -> AP2127K-ADJTRG1 | G12: =INDEX(Parts!$E$3:$E$44,MATCH($E12,Parts!$A$3:$A$44,0)) -> Extended | H12: =INDEX(Parts!$F$3:$F$44,MATCH($E12,Parts!$A$3:$A$44,0)) -> 50060 | I12: =INDEX(Parts!$G$3:$G$44,MATCH($E12,Parts!$A$3:$A$44,0)) -> 0.1269 | J12: =B12*I12 -> 0.1269 | K12: =IF(INDEX(Parts!$H$3:$H$44,MATCH($E12,Parts!$A$3:$A$44,0))="No","JLC assembly","PRE-ORDER") -> JLC assembly | L12: =IF(H12<B12*Summary!$B$5,"SHORT",IF(H12<Summary!$B$8,"Thin","OK")) -> OK | M12: https://www.diodes.com/assets/Datasheets/AP2127.pdf
A13: U3 | B13: 1 | C13: BNO055 | D13: jlc:LGA-28_L5.2-W3.8-P0.50-BL | E13: C93216 | F13: =INDEX(Parts!$B$3:$B$44,MATCH($E13,Parts!$A$3:$A$44,0)) -> BNO055 | G13: =INDEX(Parts!$E$3:$E$44,MATCH($E13,Parts!$A$3:$A$44,0)) -> Extended | H13: =INDEX(Parts!$F$3:$F$44,MATCH($E13,Parts!$A$3:$A$44,0)) -> 8957 | I13: =INDEX(Parts!$G$3:$G$44,MATCH($E13,Parts!$A$3:$A$44,0)) -> 9.3239 | J13: =B13*I13 -> 9.3239 | K13: =IF(INDEX(Parts!$H$3:$H$44,MATCH($E13,Parts!$A$3:$A$44,0))="No","JLC assembly","PRE-ORDER") -> JLC assembly | L13: =IF(H13<B13*Summary!$B$5,"SHORT",IF(H13<Summary!$B$8,"Thin","OK")) -> OK | M13: https://www.bosch-sensortec.com/media/boschsensortec/downloads/datasheets/bst-bno055-ds000.pdf
A14: Y1 | B14: 1 | C14: 32.768k | D14: jlc:FC-135R_L3.2-W1.5 | E14: C32346 | F14: =INDEX(Parts!$B$3:$B$44,MATCH($E14,Parts!$A$3:$A$44,0)) -> Q13FC13500004 | G14: =INDEX(Parts!$E$3:$E$44,MATCH($E14,Parts!$A$3:$A$44,0)) -> Basic | H14: =INDEX(Parts!$F$3:$F$44,MATCH($E14,Parts!$A$3:$A$44,0)) -> 761776 | I14: =INDEX(Parts!$G$3:$G$44,MATCH($E14,Parts!$A$3:$A$44,0)) -> 0.1714 | J14: =B14*I14 -> 0.1714 | K14: =IF(INDEX(Parts!$H$3:$H$44,MATCH($E14,Parts!$A$3:$A$44,0))="No","JLC assembly","PRE-ORDER") -> JLC assembly | L14: =IF(H14<B14*Summary!$B$5,"SHORT",IF(H14<Summary!$B$8,"Thin","OK")) -> OK | M14: https://jlcpcb.com/partdetail/C32346
A15: U2 | B15: 1 | C15: PMW3360DM-T2QU | D15: jlc:PMW3360DM-T2QU_16Pin | I15: 0 | J15: =B15*I15 -> 0 | K15: PMW3360DM-T2QU + LM19-LSI lens (Tindie/AliExpress), hand-soldered | L15: n/a | M15: https://www.trackballs.eu/media/Ploopy/Adept/PMW3360DM-T2QU.pdf
A17: Totals per board | B17: =SUM(B3:B15) -> 23 | J17: =SUM(J3:J15) -> 9.9899
A18: Extended-part lines (one-off fee each per order) | B18: =COUNTIF(G3:G15,"Extended") -> 3
A19: Lines with no JLC code (hand-soldered) | B19: =COUNTBLANK(E3:E15) -> 1
A20: Lines below thin-stock threshold | B20: =COUNTIF(L3:L15,"Thin")+COUNTIF(L3:L15,"SHORT") -> 1
A21: Lines short for the planned run | B21: =COUNTIF(L3:L15,"SHORT") -> 0

Sheet Flags
A1: Board | B1: Item | C1: Flag | D1: Why it matters | E1: Decision needed | F1: Decision
A2: Motion | B2: J2 JST-PH 2P (C295747) | C2: Rated 2 A per contact; simulated all-motor stall draws 2.45 A from the cell | D2: Contact heating under sustained stall; normal driving is well under 2 A | E2: Accept (stall is brief, driver limits at 1 A each) or move to a 3 A connector | F2: Accepted as is (Jerome, 2026-09-06)
A3: Motion | B3: R19-R22 0R5 0603 (C2934253) | C3: 80 mW of the 100 mW rating during a single-motor stall | D3: Little derating margin at 60 C+ ambient | E3: Accept or go to 0805 / 0.25 W | F3: Accepted as is (Jerome, 2026-09-06)
A4: Motion | B4: U6-U9 DRV8830 UVLO | C4: VMOT falls below the 2.75 V UVLO on a cell under ~3.3 V | D4: Motors stop before the P4 does on a flat cell | E4: Firmware cut-off near 3.3 V or accept | F4: Accepted as is (Jerome, 2026-09-06)
A5: Motion | B5: U1 ETA6003 USB draw | C5: 1.4-1.6 A from USB while charging at 806 mA and driving | D5: A 0.5 A port folds back via Vhold; needs a 1.5 A source | E5: Accept, or lower ISET / USB_DET on weak ports | F5: Accepted as is (Jerome, 2026-09-06)
A6: Vision | B6: U3 C6_IO8 (pad 10) | C6: Waveshare recommends a 10k pull-up | D6: C6 boot strap; module may boot into download mode without it in rare cases | E6: Add R (Basic 10k C25744) | F6: DONE 2026-09-07: R14 10k added (C25744), routed, DRC/parity clean
A7: Odometry/Motion | B7: Extended-part fee swaps | C7: 39R->33R (C25105), 150k/110k->47k/33k (1.939 V), 22pF 0402->0603 C0G (C1653) | D7: Four fee lines gone; Motion R17 180k stays Extended (no Basic 180k) | F7: DONE 2026-09-07
A8: Vision | B8: J3 0.5K-AS-22PWB (C2911765) | C8: Top-contact 22P connector at the bottom edge; pinout MIRRORED (pin k = Pi Zero pin 23-k) so the OV5647 spy flex lands contacts-up | D8: A wrong mirror puts 3V3 on GND and the CSI pairs backwards | E8: Continuity-check pin 1 = 3V3, pin 22 = GND, pin 6 = CAM_EN with the module in hand before powering | F8: Open: check at bring-up (473 in stock; FPC07-S22-ECA C53207220 is the alternative)
A9: Vision | B9: J7 GH1.25 6P ToF (C3029381) | C9: Side-entry on the underside, anchor pads 0.55 mm from the edge (JLC limit 0.2 mm); board pin order 3V3, GND, SDA, SCL, LPN, INT | D9: Bought VL53L5CX modules vary in pin order | E9: Match the cable to the module bought | F9: Open: cable order only
A10: Vision | B10: CSI D0 pair | C10: Rerouted 2026-09-07: 24.4/24.4 mm, one via each, 0.15 mm tracks, 0.25 mm gap; field solver 93 ohm differential, return loss 24 dB at 1 GHz | D10: Inside the 80-125 ohm MIPI window | F10: DONE 2026-09-07
A11: Vision | B11: CSI D1 pair | C11: Rerouted 2026-09-07: 25.1/25.3 mm, one via each, 0.15 mm tracks; field solver 89 ohm differential, return loss 21 dB at 1 GHz | D11: Inside the 80-125 ohm MIPI window | F11: DONE 2026-09-07
A12: Vision | B12: GND stitching after the reroute | C12: The D0/D1 reroute cut two GND fill islands (J3.16 camera GND on F.Cu, J7.2 ToF GND on B.Cu); two GND vias added | D12: Both connector GND pins were floating until the vias went in | F12: DONE 2026-09-07 (DRC 0 errors, 0 unconnected on a refilled copy)
A13: All | B13: Vias 0.45 mm on 0.2 mm drill | C13: 0.125 mm annular ring; JLC states 0.15 mm absolute minimum for multilayer | D13: JLC runs this size routinely (KiCad default) but may query it | E13: Accept, or set the Default via to 0.5 mm | F13: Open
A14: Vision | B14: SW3 MSK12C02 (C431540) | C14: Switch is on the Vision board: a Motion board alone stays OFF; lever sits above the Motion USB-C | D14: Motion cannot be tested without Vision (or a jumper J8.9 to GND) | E14: Accept | F14: Accepted (Jerome, 2026-09-07)
A15: Stack | B15: J8/J9 2x5 sockets | C15: Vision C20 (underside) sits over Motion J11 (4.25 mm tall) and the module over L2: with 4.3 mm sockets the clearance is 0.3 / 0.4 mm | D15: Too-short sockets collide | E15: 5.6 mm-high 2x5 2.00 mm sockets are REQUIRED (7.1 mm board gap) | F15: Decided 2026-09-08: 5.6 mm sockets
A16: Motion/Odometry | B16: GH10 cable J7 <-> J1 | C16: J1 is J7's mirror image (rotated 180, pins reversed), signals sit vertically above themselves | D16: A same-side (1-to-1) cable would short 3V3 to GND | E16: Buy the REVERSE / opposite-side GH1.25 10-pin cable (cavity 1 to cavity 10); test J7 pad 1 to J1 pad 10 = short before power | F16: Open: cable order
A17: Vision | B17: SW1/SW2 tact switches (C7470171) | C17: Were wired across pads 1-2, which are ONE internal bar on this 4-leg switch (drawing: 1-2 common, 3-4 common) | D17: P4 held in reset and forced into download mode: the board would not boot | E17: Footprint pads renumbered 1,1,2,2; GND on the other bar | F17: FIXED 2026-09-08 (adversarial review)
A18: Vision | B18: J3 camera enable | C18: Pi Zero pin 17 = CAM_GPIO0 (our CAM_EN), pin 18 = CAM_GPIO1 (was NC) | D18: If a module uses the other line for its LDO enable the camera never powers | E18: Pad 5 (Pi 18) also tied to CAM_EN | F18: DONE 2026-09-08
A19: Motion | B19: R8 100k gate pull-up | C19: Vgs of Q2/Q3 only -1.5 to -1.7 V on a 3.0-3.3 V cell (SI2333 characterised at -1.8 V) | D19: FETs run resistive on a flat cell | E19: R8 -> 1M (C26083, in BOM): Vgs -2.6 V at 3.0 V, harness passes, inrush 1.61 A | F19: DONE 2026-09-08: R8 = 1M (C26083)
A20: Motion | B20: RT1 NTC on the board | C20: RT1 sits 3 mm from the charger, 73 C when driving; the charger stops charging above ~40 C at that pin | D20: No charging while or shortly after driving | E20: Accept, or fit a fixed 10k instead of the NTC (no cell thermistor anyway) | F20: Kept as is: charge when parked and cool
A21: Firmware | B21: Low-battery cut-off | C21: DRV8830 drivers drop out below 2.75 V on VMOT (a 3.0 V cell under load) while the P4 runs down to 2.8 V | D21: Motors stutter and stop while the robot keeps thinking | E21: Firmware stops driving at 3.2 V on VBAT_SENSE (GPIO20 = VSYS_SW/2), warns at 3.4 V | F21: FIRMWARE RULE (see FIRMWARE_NOTES.md)
A22: Firmware | B22: USB charging while driving | C22: Charge 0.8 A + running 0.5-1 A = 1.4-1.8 A from USB; a 0.5 A port folds the charge back via Vhold | D22: Slow/no charging on weak supplies, no damage | E22: Use a 1.5-2 A USB supply; firmware reports a weak source when VBUS sags below 4.5 V while charging | F22: FIRMWARE NOTE (see FIRMWARE_NOTES.md)
A23: Motion | B23: Regen on USB without a battery | C23: Fast reversals return motor energy to VMOT; with no cell the caps take it and can exceed the 7 V driver limit | D23: Only when driving on USB with the cell removed | E23: Firmware: no hard reversal without a battery, or a 5.6 V clamp on VMOT | F23: Decided 2026-09-08: FIRMWARE RULE (coast before reversing when VBAT_SENSE shows no cell)
A24: Vision | B24: J10 WS2812 on 3V3 | C24: 3.28 V supply vs the WS2812B's 3.5 V minimum | D24: Most parts work at 3.3 V; some don't | E24: Keep, or feed J10 pin 1 from VMOT (available at J8.10) with 0.13 V data margin at 4.5 V | F24: Kept on 3V3
... A28: Vision | B28: ToF VL53L5CX | C28: JLC has the bare chip pre-order only | D28: Cannot be assembled by JLC | E28: Keep the bought module on J7 | F28: Module stays (Jerome, 2026-09-06)
